Workbook

Sheet Instructions
D8: Abu Dhabi Polytechnic Course and Students Learning Outcomes Assessment System
F11: Course Report | G11: Course Information | H11: Student Survey
F12: Course Analysis | G12: Course Syllabus | H12: Students Names and ID
F13: Homework | G13: Quizzes | H13: Final Exam
F14: Laboratory | G14: Reports & Presentations | H14: Midterm Exam
C20: Measurement Scale
C21: Score Scale | E21: Score Interpretation
C22: 1 | E22: Poor/ insufficient | G22: Poor performance, but generally meets the minimum criteria. Considerable further work is required. (Improvement action plan is required)
C23: 2 | E23: Sufficient / Satisfactory | G23: Fair performance, but with significant shortcomings. Some work is required. (Improvement action plan is required).
C24: 3 | E24: Good/Average Performance | G24: Generally sound work with number of notable errors.
C25: 4 | E25: Very good Performance | G25: Above the average standard with some errors.
C26: 5 | E26: Outstanding Performance | G26: Outstanding performance with minor error.
C29: Note | D29: If the course outcome assessment score is below 3, instructor is strongly recommended to provide program head with a report identifying areas of improvement at the course level and to suggest necessary actions to be undertaken to overcome future challenges when offering this course.

Sheet Course Information
B1: Course Title
B2: Course ID
B3: Semester / Academic Year
B4: Instructor Name
B5: Course Registration Number (CRN) / Section Number
B6: Number of Students
A9: Course Learning Outcome No. | B9: Course Learning Outcome | C9: Correspondent Student Learning Outcome
A10: 1
A11: 2
A12: 3
A13: 4
A14: 5
A15: 6
A16: 7
A17: 8
A18: 9
A19: 10
A20: 11
A21: 12
A23: Students Learning Outcome ID | B23: Student Learning Outcome Statement | C23: Course Related Outcomes
A24: 1 | B24: An ability to apply knowledge, techniques, skills and modern tools of mathematics, science, engineering, and technology to solve broadly-defined engineering problems appropriate to the discipline;
A25: 2 | B25: An ability to design systems, components, or processes meeting specified needs for broadly-defined engineering problems appropriate to the discipline;
A26: 3 | B26: An ability to apply written, oral, and graphical communication in broadly-defined technical and non-technical environments; and an ability to identify and use appropriate technical literature;
A27: 4 | B27: An ability to conduct standard tests, measurements, and experiments and to analyze and interpret the results to improve processes.
A28: 5 | B28: An ability to function effectively as a member as well as a leader on technical teams.
A29: 6 | B29: An ability to apply innovation and entrepreneurship skills to broadly defined engineering applications.
A30: 7
A31: 8
A32: 9
A33: 10
A34: 11
A35: 12
A38: PI # | B38: SO Description | C38: Contribution %
B39: An ability to apply knowledge, techniques, skills and modern tools of mathematics, science, engineering, and technology to solve broadly-defined engineering problems appropriate to the discipline; | C39: If a sub-PI is not contributing to the SO, make sure you place a 0 for its value.
A40: PI 1.a. | B40: Apply knowledge of STEM to solve broadly-defined electromechanical engineering problems appropriate to the discipline | C40: 0.25
A41: PI 1.b. | B41: Apply and techniques of STEM to solve broadly-defined electromechanical engineering problems appropriate to the discipline | C41: 0.25
A42: PI 1.c. | B42: Apply skills of STEM to solve broadly-defined electromechanical engineering problems appropriate to the discipline | C42: 0.25
A43: PI 1.d. | B43: Apply modern tools of STEM to solve broadly-defined electromechanical engineering problems appropriate to the discipline | C43: 0.25
B44: An ability to design systems, components, or processes meeting specified needs for broadly-defined engineering problems appropriate to the discipline;
A45: PI 2.a. | B45: Ability to design systems, components or process meeting specified needs for broadly-defined electromechanical engineering problems. | C45: 0.5
...

Sheet Students Names and ID
A1: No. | B1: Student Name | C1: ID
A2: 1
A3: 2
A4: 3
A5: 4
A6: 5
A7: 6
A8: 7
A9: 8
A10: 9
A11: 10
A12: 11
A13: 12
... A41: 40

Sheet Homework
A1: Homework Sheet | B1: CLO # 1
B2: CLO # 2
B3: Grade | C3: 1 | W3: Total | X3: Course Weight
A4: Student Name | B4: ID | C4: HW1 | D4: HW2 | E4: HW3 | F4: HW4 | G4: HW5 | H4: HW6 | I4: HW7 | J4: HW8 | K4: HW9 | L4: HW10 | M4: HW11 | N4: HW12 | O4: HW13 | P4: HW14 | Q4: HW15 | R4: HW16 | S4: HW17 | T4: HW18 | U4: HW19 | V4: HW20 | W4: =SUM(C3:V3) -> 1 | X4: 0
A5: ='Students Names and ID'!B2 -> 0 | B5: ='Students Names and ID'!C2 -> 0 | W5: =SUM(C5:V5) -> 0 | X5: =W5*X$4/W$4 -> 0
A6: ='Students Names and ID'!B3 -> 0 | B6: ='Students Names and ID'!C3 -> 0 | W6: =SUM(C6:V6) -> 0 | X6: =W6*X$4/W$4 -> 0
A7: ='Students Names and ID'!B4 -> 0 | B7: ='Students Names and ID'!C4 -> 0 | W7: =SUM(C7:V7) -> 0 | X7: =W7*X$4/W$4 -> 0
A8: ='Students Names and ID'!B5 -> 0 | B8: ='Students Names and ID'!C5 -> 0 | W8: =SUM(C8:V8) -> 0 | X8: =W8*X$4/W$4 -> 0
A9: ='Students Names and ID'!B6 -> 0 | B9: ='Students Names and ID'!C6 -> 0 | W9: =SUM(C9:V9) -> 0 | X9: =W9*X$4/W$4 -> 0
A10: ='Students Names and ID'!B7 -> 0 | B10: ='Students Names and ID'!C7 -> 0 | W10: =SUM(C10:V10) -> 0 | X10: =W10*X$4/W$4 -> 0
A11: ='Students Names and ID'!B8 -> 0 | B11: ='Students Names and ID'!C8 -> 0 | W11: =SUM(C11:V11) -> 0 | X11: =W11*X$4/W$4 -> 0
A12: ='Students Names and ID'!B9 -> 0 | B12: ='Students Names and ID'!C9 -> 0 | W12: =SUM(C12:V12) -> 0 | X12: =W12*X$4/W$4 -> 0
A13: ='Students Names and ID'!B10 -> 0 | B13: ='Students Names and ID'!C10 -> 0 | W13: =SUM(C13:V13) -> 0 | X13: =W13*X$4/W$4 -> 0
A14: ='Students Names and ID'!B11 -> 0 | B14: ='Students Names and ID'!C11 -> 0 | W14: =SUM(C14:V14) -> 0 | X14: =W14*X$4/W$4 -> 0
A15: ='Students Names and ID'!B12 -> 0 | B15: ='Students Names and ID'!C12 -> 0 | W15: =SUM(C15:V15) -> 0 | X15: =W15*X$4/W$4 -> 0
A16: ='Students Names and ID'!B13 -> 0 | B16: ='Students Names and ID'!C13 -> 0 | W16: =SUM(C16:V16) -> 0 | X16: =W16*X$4/W$4 -> 0
... A44: ='Students Names and ID'!B41 -> 0 | B44: ='Students Names and ID'!C41 -> 0 | W44: =SUM(C44:V44) -> 0 | X44: =W44*X$4/W$4 -> 0
B45: Average | C45: =IF(COUNTBLANK(C5:C44)=40," ",AVERAGE(C5:C44)) | D45: =IF(COUNTBLANK(D5:D44)=40," ",AVERAGE(D5:D44)) | E45: =IF(COUNTBLANK(E5:E44)=40," ",AVERAGE(E5:E44)) | F45: =IF(COUNTBLANK(F5:F44)=40," ",AVERAGE(F5:F44)) | G45: =IF(COUNTBLANK(G5:G44)=40," ",AVERAGE(G5:G44)) | H45: =IF(COUNTBLANK(H5:H44)=40," ",AVERAGE(H5:H44)) | I45: =IF(COUNTBLANK(I5:I44)=40," ",AVERAGE(I5:I44)) | J45: =IF(COUNTBLANK(J5:J44)=40," ",AVERAGE(J5:J44)) | ... V45: =IF(COUNTBLANK(V5:V44)=40," ",AVERAGE(V5:V44)) | W45: =IF(COUNTBLANK(W5:W43)=20," ",AVERAGE(W5:W44)) -> 0 | X45: =IF(COUNTBLANK(X5:X43)=20," ",AVERAGE(X5:X44)) -> 0
B46: Average of 10 | C46: =IF(C45="","",IF(ISERROR(ROUND(C45*10/C3,1))," ",(ROUND(C45*10/C3,1)))) | D46: =IF(D45="","",IF(ISERROR(ROUND(D45*10/D3,1))," ",(ROUND(D45*10/D3,1)))) | E46: =IF(E45="","",IF(ISERROR(ROUND(E45*10/E3,1))," ",(ROUND(E45*10/E3,1)))) | F46: =IF(F45="","",IF(ISERROR(ROUND(F45*10/F3,1))," ",(ROUND(F45*10/F3,1)))) | G46: =IF(G45="","",IF(ISERROR(ROUND(G45*10/G3,1))," ",(ROUND(G45*10/G3,1)))) | H46: =IF(H45="","",IF(ISERROR(ROUND(H45*10/H3,1))," ",(ROUND(H45*10/H3,1)))) | I46: =IF(I45="","",IF(ISERROR(ROUND(I45*10/I3,1))," ",(ROUND(I45*10/I3,1)))) | J46: =IF(J45="","",IF(ISERROR(ROUND(J45*10/J3,1))," ",(ROUND(J45*10/J3,1)))) | ... V46: =IF(V45="","",IF(ISERROR(ROUND(V45*10/V3,1))," ",(ROUND(V45*10/V3,1)))) | W46: =IF(W45="","",IF(ISERROR(ROUND(W45*10/W4,1))," ",(ROUND(W45*10/W4,1)))) -> 0 | X46: =IF(X45="","",IF(ISERROR(ROUND(X45*10/X4,1))," ",(ROUND(X45*10/X4,1))))
B47: ABET Pass Criteria | C47: =COUNTIF(C5:C44,">="&(0.7*C3)) -> 0 | D47: =COUNTIF(D5:D44,">="&(0.7*D3)) -> 0 | E47: =COUNTIF(E5:E44,">="&(0.7*E3)) -> 0 | F47: =COUNTIF(F5:F44,">="&(0.7*F3)) -> 0 | G47: =COUNTIF(G5:G44,">="&(0.7*G3)) -> 0 | H47: =COUNTIF(H5:H44,">="&(0.7*H3)) -> 0 | I47: =COUNTIF(I5:I44,">="&(0.7*I3)) -> 0 | J47: =COUNTIF(J5:J44,">="&(0.7*J3)) -> 0 | ... L47: =COUNTIF(L5:L44,">="&(0.7*L3)) -> 0 | M47: =COUNTIF(M5:M44,">"&(0.75*M3)) -> 0 | N47: =COUNTIF(N5:N44,">"&(0.75*N3)) -> 0 | O47: =COUNTIF(O5:O44,">"&(0.75*O3)) -> 0 | P47: =COUNTIF(P5:P44,">"&(0.75*P3)) -> 0 | Q47: =COUNTIF(Q5:Q44,">"&(0.75*Q3)) -> 0 | R47: =COUNTIF(R5:R44,">"&(0.75*R3)) -> 0 | S47: =COUNTIF(S5:S44,">"&(0.75*S3)) -> 0 | T47: =COUNTIF(T5:T44,">"&(0.75*T3)) -> 0 | ... V47: =COUNTIF(V5:V44,">"&(0.75*V3)) -> 0
C49: =C4 -> HW1 | D49: =D4 -> HW2 | E49: =E4 -> HW3 | F49: =F4 -> HW4 | G49: =G4 -> HW5 | H49: =H4 -> HW6 | I49: =I4 -> HW7 | J49: =J4 -> HW8 | ... L49: =L4 -> HW10
B50: Program PIs | C50: Fill in the colored columns with an 'x' to use the corresponding assessment against the PI | W50: Sum | X50: # of Assesments Included
C51: Do not write in the white columns
B52: PI 1.a | W52: =IF(X52=0,"",SUM(C53:L53)) | X52: =COUNT(C53:L53) -> 0
C53: =IF(C52="x",C$47,"") | D53: =IF(D52="x",D$47,"") | E53: =IF(E52="x",E$47,"") | F53: =IF(F52="x",F$47,"") | G53: =IF(G52="x",G$47,"") | H53: =IF(H52="x",H$47,"") | I53: =IF(I52="x",I$47,"") | J53: =IF(J52="x",J$47,"") | ... L53: =IF(L52="x",L$47,"")
B54: PI 1.b | W54: =IF(X54=0,"",SUM(C55:L55)) | X54: =COUNT(C55:L55) -> 0
C55: =IF(C54="x",C$47,"") | D55: =IF(D54="x",D$47,"") | E55: =IF(E54="x",E$47,"") | F55: =IF(F54="x",F$47,"") | G55: =IF(G54="x",G$47,"") | H55: =IF(H54="x",H$47,"") | I55: =IF(I54="x",I$47,"") | J55: =IF(J54="x",J$47,"") | ... L55: =IF(L54="x",L$47,"")
B56: PI 1.c | W56: =IF(X56=0,"",SUM(C57:L57)) | X56: =COUNT(C57:L57) -> 0
C57: =IF(C56="x",C$47,"") | D57: =IF(D56="x",D$47,"") | E57: =IF(E56="x",E$47,"") | F57: =IF(F56="x",F$47,"") | G57: =IF(G56="x",G$47,"") | H57: =IF(H56="x",H$47,"") | I57: =IF(I56="x",I$47,"") | J57: =IF(J56="x",J$47,"") | ... L57: =IF(L56="x",L$47,"")
B58: PI 1.d | W58: =IF(X58=0,"",SUM(C59:L59)) | X58: =COUNT(C59:L59) -> 0
C59: =IF(C58="x",C$47,"") | D59: =IF(D58="x",D$47,"") | E59: =IF(E58="x",E$47,"") | F59: =IF(F58="x",F$47,"") | G59: =IF(G58="x",G$47,"") | H59: =IF(H58="x",H$47,"") | I59: =IF(I58="x",I$47,"") | J59: =IF(J58="x",J$47,"") | ... L59: =IF(L58="x",L$47,"")
B60: PI 2.a | W60: =IF(X60=0,"",SUM(C61:L61)) | X60: =COUNT(C61:L61) -> 0
C61: =IF(C60="x",C$47,"") | D61: =IF(D60="x",D$47,"") | E61: =IF(E60="x",E$47,"") | F61: =IF(F60="x",F$47,"") | G61: =IF(G60="x",G$47,"") | H61: =IF(H60="x",H$47,"") | I61: =IF(I60="x",I$47,"") | J61: =IF(J60="x",J$47,"") | ... L61: =IF(L60="x",L$47,"")
B62: PI 2.b | W62: =IF(X62=0,"",SUM(C63:L63)) | X62: =COUNT(C63:L63) -> 0
C63: =IF(C62="x",C$47,"") | D63: =IF(D62="x",D$47,"") | E63: =IF(E62="x",E$47,"") | F63: =IF(F62="x",F$47,"") | G63: =IF(G62="x",G$47,"") | H63: =IF(H62="x",H$47,"") | I63: =IF(I62="x",I$47,"") | J63: =IF(J62="x",J$47,"") | ... L63: =IF(L62="x",L$47,"")
B64: PI 3.a | W64: =IF(X64=0,"",SUM(C65:L65)) | X64: =COUNT(C65:L65) -> 0
C65: =IF(C64="x",C$47,"") | D65: =IF(D64="x",D$47,"") | E65: =IF(E64="x",E$47,"") | F65: =IF(F64="x",F$47,"") | G65: =IF(G64="x",G$47,"") | H65: =IF(H64="x",H$47,"") | I65: =IF(I64="x",I$47,"") | J65: =IF(J64="x",J$47,"") | ... L65: =IF(L64="x",L$47,"")
B66: PI 3.b | W66: =IF(X66=0,"",SUM(C67:L67)) | X66: =COUNT(C67:L67) -> 0
C67: =IF(C66="x",C$47,"") | D67: =IF(D66="x",D$47,"") | E67: =IF(E66="x",E$47,"") | F67: =IF(F66="x",F$47,"") | G67: =IF(G66="x",G$47,"") | H67: =IF(H66="x",H$47,"") | I67: =IF(I66="x",I$47,"") | J67: =IF(J66="x",J$47,"") | ... L67: =IF(L66="x",L$47,"")
B68: PI 3.c | W68: =IF(X68=0,"",SUM(C69:L69)) | X68: =COUNT(C69:L69) -> 0
...

Sheet Quizzes
A1: Quizzes sheet | B1: CLO # 1
B2: CLO # 2
B3: Grade | C3: 1 | R3: Total | S3: Course Weight
A4: Student Name | B4: ID | C4: Quiz 1 | D4: Quiz 2 | E4: Quiz 3 | F4: Quiz 4 | G4: Quiz 5 | H4: Quiz 6 | I4: Quiz 7 | J4: Quiz 8 | K4: Quiz 9 | L4: Quiz 10 | M4: Quiz 11 | N4: Quiz 12 | O4: Quiz 13 | P4: Quiz 14 | Q4: Quiz 15 | R4: =SUM(C3:M3) -> 1 | S4: 0
A5: ='Students Names and ID'!B2 -> 0 | B5: ='Students Names and ID'!C2 -> 0 | R5: =SUM(C5:Q5) -> 0 | S5: =R5*S$4/R$4 -> 0
A6: ='Students Names and ID'!B3 -> 0 | B6: ='Students Names and ID'!C3 -> 0 | R6: =SUM(C6:Q6) -> 0 | S6: =R6*S$4/R$4 -> 0
A7: ='Students Names and ID'!B4 -> 0 | B7: ='Students Names and ID'!C4 -> 0 | R7: =SUM(C7:Q7) -> 0 | S7: =R7*S$4/R$4 -> 0
A8: ='Students Names and ID'!B5 -> 0 | B8: ='Students Names and ID'!C5 -> 0 | R8: =SUM(C8:Q8) -> 0 | S8: =R8*S$4/R$4 -> 0
A9: ='Students Names and ID'!B6 -> 0 | B9: ='Students Names and ID'!C6 -> 0 | R9: =SUM(C9:Q9) -> 0 | S9: =R9*S$4/R$4 -> 0
A10: ='Students Names and ID'!B7 -> 0 | B10: ='Students Names and ID'!C7 -> 0 | R10: =SUM(C10:Q10) -> 0 | S10: =R10*S$4/R$4 -> 0
A11: ='Students Names and ID'!B8 -> 0 | B11: ='Students Names and ID'!C8 -> 0 | R11: =SUM(C11:Q11) -> 0 | S11: =R11*S$4/R$4 -> 0
A12: ='Students Names and ID'!B9 -> 0 | B12: ='Students Names and ID'!C9 -> 0 | R12: =SUM(C12:Q12) -> 0 | S12: =R12*S$4/R$4 -> 0
A13: ='Students Names and ID'!B10 -> 0 | B13: ='Students Names and ID'!C10 -> 0 | R13: =SUM(C13:Q13) -> 0 | S13: =R13*S$4/R$4 -> 0
A14: ='Students Names and ID'!B11 -> 0 | B14: ='Students Names and ID'!C11 -> 0 | R14: =SUM(C14:Q14) -> 0 | S14: =R14*S$4/R$4 -> 0
A15: ='Students Names and ID'!B12 -> 0 | B15: ='Students Names and ID'!C12 -> 0 | R15: =SUM(C15:Q15) -> 0 | S15: =R15*S$4/R$4 -> 0
A16: ='Students Names and ID'!B13 -> 0 | B16: ='Students Names and ID'!C13 -> 0 | R16: =SUM(C16:Q16) -> 0 | S16: =R16*S$4/R$4 -> 0
... A44: ='Students Names and ID'!B41 -> 0 | B44: ='Students Names and ID'!C41 -> 0 | R44: =SUM(C44:Q44) -> 0 | S44: =R44*S$4/R$4 -> 0
B45: Average | C45: =IF(COUNTBLANK(C5:C44)=40," ",AVERAGE(C5:C44)) | D45: =IF(COUNTBLANK(D5:D44)=40," ",AVERAGE(D5:D44)) | E45: =IF(COUNTBLANK(E5:E44)=40," ",AVERAGE(E5:E44)) | F45: =IF(COUNTBLANK(F5:F44)=40," ",AVERAGE(F5:F44)) | G45: =IF(COUNTBLANK(G5:G44)=40," ",AVERAGE(G5:G44)) | H45: =IF(COUNTBLANK(H5:H44)=40," ",AVERAGE(H5:H44)) | I45: =IF(COUNTBLANK(I5:I44)=40," ",AVERAGE(I5:I44)) | J45: =IF(COUNTBLANK(J5:J44)=40," ",AVERAGE(J5:J44)) | ... S45: =IF(COUNTBLANK(S5:S44)=40," ",AVERAGE(S5:S44)) -> 0
B46: Average of 10 | C46: =IF(C45="","",IF(ISERROR(ROUND(C45*10/C3,1))," ",(ROUND(C45*10/C3,1)))) | D46: =IF(D45="","",IF(ISERROR(ROUND(D45*10/D3,1))," ",(ROUND(D45*10/D3,1)))) | E46: =IF(E45="","",IF(ISERROR(ROUND(E45*10/E3,1))," ",(ROUND(E45*10/E3,1)))) | F46: =IF(F45="","",IF(ISERROR(ROUND(F45*10/F3,1))," ",(ROUND(F45*10/F3,1)))) | G46: =IF(G45="","",IF(ISERROR(ROUND(G45*10/G3,1))," ",(ROUND(G45*10/G3,1)))) | H46: =IF(H45="","",IF(ISERROR(ROUND(H45*10/H3,1))," ",(ROUND(H45*10/H3,1)))) | I46: =IF(I45="","",IF(ISERROR(ROUND(I45*10/I3,1))," ",(ROUND(I45*10/I3,1)))) | J46: =IF(J45="","",IF(ISERROR(ROUND(J45*10/J3,1))," ",(ROUND(J45*10/J3,1)))) | ... Q46: =IF(Q45="","",IF(ISERROR(ROUND(Q45*10/Q3,1))," ",(ROUND(Q45*10/Q3,1)))) | R46: =IF(R45="","",IF(ISERROR(ROUND(R45*10/R4,1))," ",(ROUND(R45*10/R4,1)))) -> 0 | S46: =IF(S45="","",IF(ISERROR(ROUND(S45*10/S4,1))," ",(ROUND(S45*10/S4,1))))
B47: ABET Pass Criteria | C47: =COUNTIF(C5:C44,">="&(0.7*C3)) -> 0 | D47: =COUNTIF(D5:D44,">="&(0.7*D3)) -> 0 | E47: =COUNTIF(E5:E44,">="&(0.7*E3)) -> 0 | F47: =COUNTIF(F5:F44,">="&(0.7*F3)) -> 0 | G47: =COUNTIF(G5:G44,">="&(0.7*G3)) -> 0 | H47: =COUNTIF(H5:H44,">="&(0.7*H3)) -> 0 | I47: =COUNTIF(I5:I44,">="&(0.7*I3)) -> 0 | J47: =COUNTIF(J5:J44,">="&(0.7*J3)) -> 0 | ... L47: =COUNTIF(L5:L44,">="&(0.7*L3)) -> 0 | M47: =COUNTIF(M5:M44,">"&(0.75*M3)) -> 0 | N47: =COUNTIF(N5:N44,">"&(0.75*N3)) -> 0 | O47: =COUNTIF(O5:O44,">"&(0.75*O3)) -> 0 | P47: =COUNTIF(P5:P44,">"&(0.75*P3)) -> 0 | Q47: =COUNTIF(Q5:Q44,">"&(0.75*Q3)) -> 0
C49: =C4 -> Quiz 1 | D49: =D4 -> Quiz 2 | E49: =E4 -> Quiz 3 | F49: =F4 -> Quiz 4 | G49: =G4 -> Quiz 5 | H49: =H4 -> Quiz 6 | I49: =I4 -> Quiz 7 | J49: =J4 -> Quiz 8 | ... L49: =L4 -> Quiz 10
B50: Program PIs | C50: Fill in the colored columns with an 'x' to use the corresponding assessment against the PI | R50: Sum | S50: # of Assesments Included
C51: Do not write in the white columns
B52: PI 1.a | R52: =IF(S52=0,"",SUM(C53:L53)) | S52: =COUNT(C53:L53) -> 0
C53: =IF(C52="x",C47,"") | D53: =IF(D52="x",D47,"") | E53: =IF(E52="x",E47,"") | F53: =IF(F52="x",F47,"") | G53: =IF(G52="x",G47,"") | H53: =IF(H52="x",H47,"") | I53: =IF(I52="x",I47,"") | J53: =IF(J52="x",J47,"") | ... L53: =IF(L52="x",L47,"")
B54: PI 1.b | R54: =IF(S54=0,"",SUM(C55:L55)) | S54: =COUNT(C55:L55) -> 0
C55: =IF(C54="x",C47,"") | D55: =IF(D54="x",D47,"") | E55: =IF(E54="x",E47,"") | F55: =IF(F54="x",F47,"") | G55: =IF(G54="x",G47,"") | H55: =IF(H54="x",H47,"") | I55: =IF(I54="x",I47,"") | J55: =IF(J54="x",J47,"") | ... L55: =IF(L54="x",L47,"")
B56: PI 1.c | R56: =IF(S56=0,"",SUM(C57:L57)) | S56: =COUNT(C57:L57) -> 0
C57: =IF(C56="x",C47,"") | D57: =IF(D56="x",D47,"") | E57: =IF(E56="x",E47,"") | F57: =IF(F56="x",F47,"") | G57: =IF(G56="x",G47,"") | H57: =IF(H56="x",H47,"") | I57: =IF(I56="x",I47,"") | J57: =IF(J56="x",J47,"") | ... L57: =IF(L56="x",L47,"")
B58: PI 1.d | R58: =IF(S58=0,"",SUM(C59:L59)) | S58: =COUNT(C59:L59) -> 0
C59: =IF(C58="x",C47,"") | D59: =IF(D58="x",D47,"") | E59: =IF(E58="x",E47,"") | F59: =IF(F58="x",F47,"") | G59: =IF(G58="x",G47,"") | H59: =IF(H58="x",H47,"") | I59: =IF(I58="x",I47,"") | J59: =IF(J58="x",J47,"") | ... L59: =IF(L58="x",L47,"")
B60: PI 2.a | R60: =IF(S60=0,"",SUM(C61:L61)) | S60: =COUNT(C61:L61) -> 0
C61: =IF(C60="x",C47,"") | D61: =IF(D60="x",D47,"") | E61: =IF(E60="x",E47,"") | F61: =IF(F60="x",F47,"") | G61: =IF(G60="x",G47,"") | H61: =IF(H60="x",H47,"") | I61: =IF(I60="x",I47,"") | J61: =IF(J60="x",J47,"") | ... L61: =IF(L60="x",L47,"")
B62: PI 2.b | R62: =IF(S62=0,"",SUM(C63:L63)) | S62: =COUNT(C63:L63) -> 0
C63: =IF(C62="x",C47,"") | D63: =IF(D62="x",D47,"") | E63: =IF(E62="x",E47,"") | F63: =IF(F62="x",F47,"") | G63: =IF(G62="x",G47,"") | H63: =IF(H62="x",H47,"") | I63: =IF(I62="x",I47,"") | J63: =IF(J62="x",J47,"") | ... L63: =IF(L62="x",L47,"")
B64: PI 3.a | R64: =IF(S64=0,"",SUM(C65:L65)) | S64: =COUNT(C65:L65) -> 0
C65: =IF(C64="x",C47,"") | D65: =IF(D64="x",D47,"") | E65: =IF(E64="x",E47,"") | F65: =IF(F64="x",F47,"") | G65: =IF(G64="x",G47,"") | H65: =IF(H64="x",H47,"") | I65: =IF(I64="x",I47,"") | J65: =IF(J64="x",J47,"") | ... L65: =IF(L64="x",L47,"")
B66: PI 3.b | R66: =IF(S66=0,"",SUM(C67:L67)) | S66: =COUNT(C67:L67) -> 0
C67: =IF(C66="x",C47,"") | D67: =IF(D66="x",D47,"") | E67: =IF(E66="x",E47,"") | F67: =IF(F66="x",F47,"") | G67: =IF(G66="x",G47,"") | H67: =IF(H66="x",H47,"") | I67: =IF(I66="x",I47,"") | J67: =IF(J66="x",J47,"") | ... L67: =IF(L66="x",L47,"")
B68: PI 3.c | R68: =IF(S68=0,"",SUM(C69:L69)) | S68: =COUNT(C69:L69) -> 0
...

Sheet Laboratory
A1: Laboratory Sheet | B1: CLO # 1
B2: CLO # 2
B3: Grade | C3: 1 | Q3: Total Excluding Lab Final | R3: Course Weight ( including Lab final)
A4: Student Name | B4: ID | C4: Lab 1 | D4: Lab 2 | E4: Lab 3 | F4: Lab 4 | G4: Lab 5 | H4: Lab 6 | I4: Lab 7 | J4: Lab 8 | K4: Lab 9 | L4: Lab 10 | M4: Lab 7 | N4: Lab 8 | O4: Lab 9 | P4: Lab 10 | Q4: =SUM(C3:P3) -> 1 | R4: 0
A5: ='Students Names and ID'!B2 -> 0 | B5: ='Students Names and ID'!C2 -> 0 | Q5: =SUM(C5:P5) -> 0 | R5: =(Q5*R$4/Q$4) +'Laboratory Final'!N5 -> 0
A6: ='Students Names and ID'!B3 -> 0 | B6: ='Students Names and ID'!C3 -> 0 | Q6: =SUM(C6:P6) -> 0 | R6: =(Q6*R$4/Q$4) +'Laboratory Final'!N6 -> 0
A7: ='Students Names and ID'!B4 -> 0 | B7: ='Students Names and ID'!C4 -> 0 | Q7: =SUM(C7:P7) -> 0 | R7: =(Q7*R$4/Q$4) +'Laboratory Final'!N7 -> 0
A8: ='Students Names and ID'!B5 -> 0 | B8: ='Students Names and ID'!C5 -> 0 | Q8: =SUM(C8:P8) -> 0 | R8: =(Q8*R$4/Q$4) +'Laboratory Final'!N8 -> 0
A9: ='Students Names and ID'!B6 -> 0 | B9: ='Students Names and ID'!C6 -> 0 | Q9: =SUM(C9:P9) -> 0 | R9: =(Q9*R$4/Q$4) +'Laboratory Final'!N9 -> 0
A10: ='Students Names and ID'!B7 -> 0 | B10: ='Students Names and ID'!C7 -> 0 | Q10: =SUM(C10:P10) -> 0 | R10: =(Q10*R$4/Q$4) +'Laboratory Final'!N10 -> 0
A11: ='Students Names and ID'!B8 -> 0 | B11: ='Students Names and ID'!C8 -> 0 | Q11: =SUM(C11:P11) -> 0 | R11: =(Q11*R$4/Q$4) +'Laboratory Final'!N11 -> 0
A12: ='Students Names and ID'!B9 -> 0 | B12: ='Students Names and ID'!C9 -> 0 | Q12: =SUM(C12:P12) -> 0 | R12: =(Q12*R$4/Q$4) +'Laboratory Final'!N12 -> 0
A13: ='Students Names and ID'!B10 -> 0 | B13: ='Students Names and ID'!C10 -> 0 | Q13: =SUM(C13:P13) -> 0 | R13: =(Q13*R$4/Q$4) +'Laboratory Final'!N13 -> 0
A14: ='Students Names and ID'!B11 -> 0 | B14: ='Students Names and ID'!C11 -> 0 | Q14: =SUM(C14:P14) -> 0 | R14: =(Q14*R$4/Q$4) +'Laboratory Final'!N14 -> 0
A15: ='Students Names and ID'!B12 -> 0 | B15: ='Students Names and ID'!C12 -> 0 | Q15: =SUM(C15:P15) -> 0 | R15: =(Q15*R$4/Q$4) +'Laboratory Final'!N15 -> 0
A16: ='Students Names and ID'!B13 -> 0 | B16: ='Students Names and ID'!C13 -> 0 | Q16: =SUM(C16:P16) -> 0 | R16: =(Q16*R$4/Q$4) +'Laboratory Final'!N16 -> 0
... A44: ='Students Names and ID'!B41 -> 0 | B44: ='Students Names and ID'!C41 -> 0 | Q44: =SUM(C44:P44) -> 0 | R44: =(Q44*R$4/Q$4) +'Laboratory Final'!N44 -> 0
B45: Average | C45: =IF(COUNTBLANK(C5:C44)=40," ",AVERAGE(C5:C44)) | D45: =IF(COUNTBLANK(D5:D44)=40," ",AVERAGE(D5:D44)) | E45: =IF(COUNTBLANK(E5:E44)=40," ",AVERAGE(E5:E44)) | F45: =IF(COUNTBLANK(F5:F44)=40," ",AVERAGE(F5:F44)) | G45: =IF(COUNTBLANK(G5:G44)=40," ",AVERAGE(G5:G44)) | H45: =IF(COUNTBLANK(H5:H44)=40," ",AVERAGE(H5:H44)) | I45: =IF(COUNTBLANK(I5:I44)=40," ",AVERAGE(I5:I44)) | J45: =IF(COUNTBLANK(J5:J44)=40," ",AVERAGE(J5:J44)) | ... R45: =IF(COUNTBLANK(R5:R44)=40," ",AVERAGE(R5:R44)) -> 0
B46: Average of 10 | C46: =IF(C45="","",IF(ISERROR(ROUND(C45*10/C3,1))," ",(ROUND(C45*10/C3,1)))) | D46: =IF(D45="","",IF(ISERROR(ROUND(D45*10/D3,1))," ",(ROUND(D45*10/D3,1)))) | E46: =IF(E45="","",IF(ISERROR(ROUND(E45*10/E3,1))," ",(ROUND(E45*10/E3,1)))) | F46: =IF(F45="","",IF(ISERROR(ROUND(F45*10/F3,1))," ",(ROUND(F45*10/F3,1)))) | G46: =IF(G45="","",IF(ISERROR(ROUND(G45*10/G3,1))," ",(ROUND(G45*10/G3,1)))) | H46: =IF(H45="","",IF(ISERROR(ROUND(H45*10/H3,1))," ",(ROUND(H45*10/H3,1)))) | I46: =IF(I45="","",IF(ISERROR(ROUND(I45*10/I3,1))," ",(ROUND(I45*10/I3,1)))) | J46: =IF(J45="","",IF(ISERROR(ROUND(J45*10/J3,1))," ",(ROUND(J45*10/J3,1)))) | ... P46: =IF(P45="","",IF(ISERROR(ROUND(P45*10/P3,1))," ",(ROUND(P45*10/P3,1)))) | Q46: =IF(Q45="","",IF(ISERROR(ROUND(Q45*10/Q4,1))," ",(ROUND(Q45*10/Q4,1)))) -> 0 | R46: =IF(R45="","",IF(ISERROR(ROUND(R45*10/R4,1))," ",(ROUND(R45*10/R4,1))))
B47: ABET Pass Criteria | C47: =COUNTIF(C5:C44,">="&(0.7*C3)) -> 0 | D47: =COUNTIF(D5:D44,">="&(0.7*D3)) -> 0 | E47: =COUNTIF(E5:E44,">="&(0.7*E3)) -> 0 | F47: =COUNTIF(F5:F44,">="&(0.7*F3)) -> 0 | G47: =COUNTIF(G5:G44,">="&(0.7*G3)) -> 0 | H47: =COUNTIF(H5:H44,">="&(0.7*H3)) -> 0 | I47: =COUNTIF(I5:I44,">="&(0.7*I3)) -> 0 | J47: =COUNTIF(J5:J44,">="&(0.7*J3)) -> 0 | ... L47: =COUNTIF(L5:L44,">="&(0.7*L3)) -> 0 | M47: =COUNTIF(M5:M44,">"&(0.75*M3)) -> 0 | N47: =COUNTIF(N5:N44,">"&(0.75*N3)) -> 0 | O47: =COUNTIF(O5:O44,">"&(0.75*O3)) -> 0 | P47: =COUNTIF(P5:P44,">"&(0.75*P3)) -> 0
C49: =C4 -> Lab 1 | D49: =D4 -> Lab 2 | E49: =E4 -> Lab 3 | F49: =F4 -> Lab 4 | G49: =G4 -> Lab 5 | H49: =H4 -> Lab 6 | I49: =I4 -> Lab 7 | J49: =J4 -> Lab 8 | ... L49: =L4 -> Lab 10
B50: Program PIs | C50: Fill in the colored columns with an 'x' to use the corresponding assessment against the PI | Q50: Sum | R50: # of Assesments Included
C51: Do not write in the white columns
B52: PI 1.a | Q52: =IF(R52=0,"",SUM(C53:L53)) | R52: =COUNT(C53:L53) -> 0
C53: =IF(C52="x",C47,"") | D53: =IF(D52="x",D47,"") | E53: =IF(E52="x",E47,"") | F53: =IF(F52="x",F47,"") | G53: =IF(G52="x",G47,"") | H53: =IF(H52="x",H47,"") | I53: =IF(I52="x",I47,"") | J53: =IF(J52="x",J47,"") | ... L53: =IF(L52="x",L47,"")
B54: PI 1.b | Q54: =IF(R54=0,"",SUM(C55:L55)) | R54: =COUNT(C55:L55) -> 0
C55: =IF(C54="x",C47,"") | D55: =IF(D54="x",D47,"") | E55: =IF(E54="x",E47,"") | F55: =IF(F54="x",F47,"") | G55: =IF(G54="x",G47,"") | H55: =IF(H54="x",H47,"") | I55: =IF(I54="x",I47,"") | J55: =IF(J54="x",J47,"") | ... L55: =IF(L54="x",L47,"")
B56: PI 1.c | Q56: =IF(R56=0,"",SUM(C57:L57)) | R56: =COUNT(C57:L57) -> 0
C57: =IF(C56="x",C47,"") | D57: =IF(D56="x",D47,"") | E57: =IF(E56="x",E47,"") | F57: =IF(F56="x",F47,"") | G57: =IF(G56="x",G47,"") | H57: =IF(H56="x",H47,"") | I57: =IF(I56="x",I47,"") | J57: =IF(J56="x",J47,"") | ... L57: =IF(L56="x",L47,"")
B58: PI 1.d | Q58: =IF(R58=0,"",SUM(C59:L59)) | R58: =COUNT(C59:L59) -> 0
C59: =IF(C58="x",C47,"") | D59: =IF(D58="x",D47,"") | E59: =IF(E58="x",E47,"") | F59: =IF(F58="x",F47,"") | G59: =IF(G58="x",G47,"") | H59: =IF(H58="x",H47,"") | I59: =IF(I58="x",I47,"") | J59: =IF(J58="x",J47,"") | ... L59: =IF(L58="x",L47,"")
B60: PI 2.a | Q60: =IF(R60=0,"",SUM(C61:L61)) | R60: =COUNT(C61:L61) -> 0
C61: =IF(C60="x",C47,"") | D61: =IF(D60="x",D47,"") | E61: =IF(E60="x",E47,"") | F61: =IF(F60="x",F47,"") | G61: =IF(G60="x",G47,"") | H61: =IF(H60="x",H47,"") | I61: =IF(I60="x",I47,"") | J61: =IF(J60="x",J47,"") | ... L61: =IF(L60="x",L47,"")
B62: PI 2.b | Q62: =IF(R62=0,"",SUM(C63:L63)) | R62: =COUNT(C63:L63) -> 0
C63: =IF(C62="x",C47,"") | D63: =IF(D62="x",D47,"") | E63: =IF(E62="x",E47,"") | F63: =IF(F62="x",F47,"") | G63: =IF(G62="x",G47,"") | H63: =IF(H62="x",H47,"") | I63: =IF(I62="x",I47,"") | J63: =IF(J62="x",J47,"") | ... L63: =IF(L62="x",L47,"")
B64: PI 3.a | Q64: =IF(R64=0,"",SUM(C65:L65)) | R64: =COUNT(C65:L65) -> 0
C65: =IF(C64="x",C47,"") | D65: =IF(D64="x",D47,"") | E65: =IF(E64="x",E47,"") | F65: =IF(F64="x",F47,"") | G65: =IF(G64="x",G47,"") | H65: =IF(H64="x",H47,"") | I65: =IF(I64="x",I47,"") | J65: =IF(J64="x",J47,"") | ... L65: =IF(L64="x",L47,"")
B66: PI 3.b | Q66: =IF(R66=0,"",SUM(C67:L67)) | R66: =COUNT(C67:L67) -> 0
C67: =IF(C66="x",C47,"") | D67: =IF(D66="x",D47,"") | E67: =IF(E66="x",E47,"") | F67: =IF(F66="x",F47,"") | G67: =IF(G66="x",G47,"") | H67: =IF(H66="x",H47,"") | I67: =IF(I66="x",I47,"") | J67: =IF(J66="x",J47,"") | ... L67: =IF(L66="x",L47,"")
B68: PI 3.c | Q68: =IF(R68=0,"",SUM(C69:L69)) | R68: =COUNT(C69:L69) -> 0
...

Sheet Laboratory Final
A1: Laboratory Final - Sheet | B1: CLO # 1 | M1: Enter the lab final percent in cell N2 (e.g. 20, 30, 50, etc..)
B2: CLO # 2 | M2: Lab Final Percent:
B3: Grade | C3: 1 | M3: Total | N3: Course Weight
A4: Student Name | B4: ID | C4: Task 1 | D4: Task 2 | E4: Task3 | F4: Task4 | G4: Task5 | H4: Task 6 | I4: Task 7 | J4: Task 8 | K4: Task 9 | L4: Task 10 | M4: =SUM(C3:L3) -> 1 | N4: =(Laboratory!R4 *N2)/100 -> 0
A5: ='Students Names and ID'!B2 -> 0 | B5: ='Students Names and ID'!C2 -> 0 | M5: =SUM(C5:L5) -> 0 | N5: =M5*N4/M4 -> 0
A6: ='Students Names and ID'!B3 -> 0 | B6: ='Students Names and ID'!C3 -> 0 | M6: =SUM(C6:L6) -> 0 | N6: =M6*N4/M4 -> 0
A7: ='Students Names and ID'!B4 -> 0 | B7: ='Students Names and ID'!C4 -> 0 | M7: =SUM(C7:L7) -> 0 | N7: =M7*N4/M4 -> 0
A8: ='Students Names and ID'!B5 -> 0 | B8: ='Students Names and ID'!C5 -> 0 | M8: =SUM(C8:L8) -> 0 | N8: =M8*N4/M4 -> 0
A9: ='Students Names and ID'!B6 -> 0 | B9: ='Students Names and ID'!C6 -> 0 | M9: =SUM(C9:L9) -> 0 | N9: =M9*N4/M4 -> 0
A10: ='Students Names and ID'!B7 -> 0 | B10: ='Students Names and ID'!C7 -> 0 | M10: =SUM(C10:L10) -> 0 | N10: =M10*N4/M4 -> 0
A11: ='Students Names and ID'!B8 -> 0 | B11: ='Students Names and ID'!C8 -> 0 | M11: =SUM(C11:L11) -> 0 | N11: =M11*N4/M4 -> 0
A12: ='Students Names and ID'!B9 -> 0 | B12: ='Students Names and ID'!C9 -> 0 | M12: =SUM(C12:L12) -> 0 | N12: =M12*N4/M4 -> 0
A13: ='Students Names and ID'!B10 -> 0 | B13: ='Students Names and ID'!C10 -> 0 | M13: =SUM(C13:L13) -> 0 | N13: =M13*N4/M4 -> 0
A14: ='Students Names and ID'!B11 -> 0 | B14: ='Students Names and ID'!C11 -> 0 | M14: =SUM(C14:L14) -> 0 | N14: =M14*N4/M4 -> 0
A15: ='Students Names and ID'!B12 -> 0 | B15: ='Students Names and ID'!C12 -> 0 | M15: =SUM(C15:L15) -> 0 | N15: =M15*N4/M4 -> 0
A16: ='Students Names and ID'!B13 -> 0 | B16: ='Students Names and ID'!C13 -> 0 | M16: =SUM(C16:L16) -> 0 | N16: =M16*N4/M4 -> 0
A17: ='Students Names and ID'!B14 -> 0 | B17: ='Students Names and ID'!C14 -> 0 | M17: =SUM(C17:L17) -> 0 | N17: =M17*N4/M4 -> 0
A18: ='Students Names and ID'!B15 -> 0 | B18: ='Students Names and ID'!C15 -> 0 | M18: =SUM(C18:L18) -> 0 | N18: =M18*N4/M4 -> 0
A19: ='Students Names and ID'!B16 -> 0 | B19: ='Students Names and ID'!C16 -> 0 | M19: =SUM(C19:L19) -> 0 | N19: =M19*N4/M4 -> 0
A20: ='Students Names and ID'!B17 -> 0 | B20: ='Students Names and ID'!C17 -> 0 | M20: =SUM(C20:L20) -> 0 | N20: =M20*N4/M4 -> 0
A21: ='Students Names and ID'!B18 -> 0 | B21: ='Students Names and ID'!C18 -> 0 | M21: =SUM(C21:L21) -> 0 | N21: =M21*N4/M4 -> 0
A22: ='Students Names and ID'!B19 -> 0 | B22: ='Students Names and ID'!C19 -> 0 | M22: =SUM(C22:L22) -> 0 | N22: =M22*N4/M4 -> 0
A23: ='Students Names and ID'!B20 -> 0 | B23: ='Students Names and ID'!C20 -> 0 | M23: =SUM(C23:L23) -> 0 | N23: =M23*N4/M4 -> 0
A24: ='Students Names and ID'!B21 -> 0 | B24: ='Students Names and ID'!C21 -> 0 | M24: =SUM(C24:L24) -> 0 | N24: =M24*N4/M4 -> 0
A25: ='Students Names and ID'!B22 -> 0 | B25: ='Students Names and ID'!C22 -> 0 | M25: =SUM(C25:L25) -> 0 | N25: =M25*N4/M4 -> 0
A26: ='Students Names and ID'!B23 -> 0 | B26: ='Students Names and ID'!C23 -> 0 | M26: =SUM(C26:L26) -> 0 | N26: =M26*N4/M4 -> 0
A27: ='Students Names and ID'!B24 -> 0 | B27: ='Students Names and ID'!C24 -> 0 | M27: =SUM(C27:L27) -> 0 | N27: =M27*N4/M4 -> 0
A28: ='Students Names and ID'!B25 -> 0 | B28: ='Students Names and ID'!C25 -> 0 | M28: =SUM(C28:L28) -> 0 | N28: =M28*N4/M4 -> 0
A29: ='Students Names and ID'!B26 -> 0 | B29: ='Students Names and ID'!C26 -> 0 | M29: =SUM(C29:L29) -> 0 | N29: =M29*N4/M4 -> 0
A30: ='Students Names and ID'!B27 -> 0 | B30: ='Students Names and ID'!C27 -> 0 | M30: =SUM(C30:L30) -> 0 | N30: =M30*N4/M4 -> 0
A31: ='Students Names and ID'!B28 -> 0 | B31: ='Students Names and ID'!C28 -> 0 | M31: =SUM(C31:L31) -> 0 | N31: =M31*N4/M4 -> 0
A32: ='Students Names and ID'!B29 -> 0 | B32: ='Students Names and ID'!C29 -> 0 | M32: =SUM(C32:L32) -> 0 | N32: =M32*N4/M4 -> 0
A33: ='Students Names and ID'!B30 -> 0 | B33: ='Students Names and ID'!C30 -> 0 | M33: =SUM(C33:L33) -> 0 | N33: =M33*N4/M4 -> 0
A34: ='Students Names and ID'!B31 -> 0 | B34: ='Students Names and ID'!C31 -> 0 | M34: =SUM(C34:L34) -> 0 | N34: =M34*N4/M4 -> 0
A35: ='Students Names and ID'!B32 -> 0 | B35: ='Students Names and ID'!C32 -> 0 | M35: =SUM(C35:L35) -> 0 | N35: =M35*N4/M4 -> 0
A36: ='Students Names and ID'!B33 -> 0 | B36: ='Students Names and ID'!C33 -> 0 | M36: =SUM(C36:L36) -> 0 | N36: =M36*N4/M4 -> 0
A37: ='Students Names and ID'!B34 -> 0 | B37: ='Students Names and ID'!C34 -> 0 | M37: =SUM(C37:L37) -> 0 | N37: =M37*N4/M4 -> 0
A38: ='Students Names and ID'!B35 -> 0 | B38: ='Students Names and ID'!C35 -> 0 | M38: =SUM(C38:L38) -> 0 | N38: =M38*N4/M4 -> 0
A39: ='Students Names and ID'!B36 -> 0 | B39: ='Students Names and ID'!C36 -> 0 | M39: =SUM(C39:L39) -> 0 | N39: =M39*N4/M4 -> 0
A40: ='Students Names and ID'!B37 -> 0 | B40: ='Students Names and ID'!C37 -> 0 | M40: =SUM(C40:L40) -> 0 | N40: =M40*N4/M4 -> 0
...

Sheet Midterm 1
A1: Midterm Exam Sheet | B1: CLO # 1
B2: CLO # 2
B4: Grade | C4: 1 | AG4: Total | AH4: Course Weight
A5: Student Name | B5: ID | C5: Q 1 | D5: Q 2 | E5: Q 3 | F5: Q 4 | G5: Q 5 | H5: Q 6 | I5: Q 7 | J5: Q 8 | K5: Q 9 | L5: Q 10 | M5: Q 11 | N5: Q 12 | O5: Q13 | P5: Q 14 | Q5: Q15 | R5: Q16 | S5: Q17 | T5: Q18 | U5: Q19 | V5: Q20 | W5: Q21 | X5: Q22 | Y5: Q23 | Z5: Q24 | AA5: Q25 | AB5: Q26 | AC5: Q27 | AD5: Q28 | AE5: Q29 | AF5: Q30 | AG5: =SUM(C4:AF4) -> 1 | AH5: 0
A6: ='Students Names and ID'!B2 -> 0 | B6: ='Students Names and ID'!C2 -> 0 | AG6: =SUM(C6:AF6) -> 0 | AH6: =AG6*AH$5/AG$5 -> 0
A7: ='Students Names and ID'!B3 -> 0 | B7: ='Students Names and ID'!C3 -> 0 | AG7: =SUM(C7:AF7) -> 0 | AH7: =AG7*AH$5/AG$5 -> 0
A8: ='Students Names and ID'!B4 -> 0 | B8: ='Students Names and ID'!C4 -> 0 | AG8: =SUM(C8:AF8) -> 0 | AH8: =AG8*AH$5/AG$5 -> 0
A9: ='Students Names and ID'!B5 -> 0 | B9: ='Students Names and ID'!C5 -> 0 | AG9: =SUM(C9:AF9) -> 0 | AH9: =AG9*AH$5/AG$5 -> 0
A10: ='Students Names and ID'!B6 -> 0 | B10: ='Students Names and ID'!C6 -> 0 | AG10: =SUM(C10:AF10) -> 0 | AH10: =AG10*AH$5/AG$5 -> 0
A11: ='Students Names and ID'!B7 -> 0 | B11: ='Students Names and ID'!C7 -> 0 | AG11: =SUM(C11:AF11) -> 0 | AH11: =AG11*AH$5/AG$5 -> 0
A12: ='Students Names and ID'!B8 -> 0 | B12: ='Students Names and ID'!C8 -> 0 | AG12: =SUM(C12:AF12) -> 0 | AH12: =AG12*AH$5/AG$5 -> 0
A13: ='Students Names and ID'!B9 -> 0 | B13: ='Students Names and ID'!C9 -> 0 | AG13: =SUM(C13:AF13) -> 0 | AH13: =AG13*AH$5/AG$5 -> 0
A14: ='Students Names and ID'!B10 -> 0 | B14: ='Students Names and ID'!C10 -> 0 | AG14: =SUM(C14:AF14) -> 0 | AH14: =AG14*AH$5/AG$5 -> 0
A15: ='Students Names and ID'!B11 -> 0 | B15: ='Students Names and ID'!C11 -> 0 | AG15: =SUM(C15:AF15) -> 0 | AH15: =AG15*AH$5/AG$5 -> 0
A16: ='Students Names and ID'!B12 -> 0 | B16: ='Students Names and ID'!C12 -> 0 | AG16: =SUM(C16:AF16) -> 0 | AH16: =AG16*AH$5/AG$5 -> 0
A17: ='Students Names and ID'!B13 -> 0 | B17: ='Students Names and ID'!C13 -> 0 | AG17: =SUM(C17:AF17) -> 0 | AH17: =AG17*AH$5/AG$5 -> 0
... A45: ='Students Names and ID'!B41 -> 0 | B45: ='Students Names and ID'!C41 -> 0 | AG45: =SUM(C45:AF45) -> 0 | AH45: =AG45*AH$5/AG$5 -> 0
B46: Average | C46: =IF(COUNTBLANK(C6:C45)=40," ",AVERAGE(C6:C45)) | D46: =IF(COUNTBLANK(D6:D45)=40," ",AVERAGE(D6:D45)) | E46: =IF(COUNTBLANK(E6:E45)=40," ",AVERAGE(E6:E45)) | F46: =IF(COUNTBLANK(F6:F45)=40," ",AVERAGE(F6:F45)) | G46: =IF(COUNTBLANK(G6:G45)=40," ",AVERAGE(G6:G45)) | H46: =IF(COUNTBLANK(H6:H45)=40," ",AVERAGE(H6:H45)) | I46: =IF(COUNTBLANK(I6:I45)=40," ",AVERAGE(I6:I45)) | J46: =IF(COUNTBLANK(J6:J45)=40," ",AVERAGE(J6:J45)) | ... AH46: =IF(COUNTBLANK(AH6:AH45)=40," ",AVERAGE(AH6:AH45)) -> 0
B47: Average of 10 | C47: =IF(C46="","",IF(ISERROR(ROUND(C46*10/C4,1))," ",(ROUND(C46*10/C4,1)))) | D47: =IF(D46="","",IF(ISERROR(ROUND(D46*10/D4,1))," ",(ROUND(D46*10/D4,1)))) | E47: =IF(E46="","",IF(ISERROR(ROUND(E46*10/E4,1))," ",(ROUND(E46*10/E4,1)))) | F47: =IF(F46="","",IF(ISERROR(ROUND(F46*10/F4,1))," ",(ROUND(F46*10/F4,1)))) | G47: =IF(G46="","",IF(ISERROR(ROUND(G46*10/G4,1))," ",(ROUND(G46*10/G4,1)))) | H47: =IF(H46="","",IF(ISERROR(ROUND(H46*10/H4,1))," ",(ROUND(H46*10/H4,1)))) | I47: =IF(I46="","",IF(ISERROR(ROUND(I46*10/I4,1))," ",(ROUND(I46*10/I4,1)))) | J47: =IF(J46="","",IF(ISERROR(ROUND(J46*10/J4,1))," ",(ROUND(J46*10/J4,1)))) | ... AF47: =IF(AF46="","",IF(ISERROR(ROUND(AF46*10/AF4,1))," ",(ROUND(AF46*10/AF4,1)))) | AG47: =IF(AG46="","",IF(ISERROR(ROUND(AG46*10/AG5,1))," ",(ROUND(AG46*10/AG5,1)))) -> 0 | AH47: =IF(AH46="","",IF(ISERROR(ROUND(AH46*10/AH5,1))," ",(ROUND(AH46*10/AH5,1))))
B48: ABET Pass Criteria | C48: =COUNTIF(C6:C45,">="&(0.7*C4)) -> 0 | D48: =COUNTIF(D6:D45,">="&(0.7*D4)) -> 0 | E48: =COUNTIF(E6:E45,">="&(0.7*E4)) -> 0 | F48: =COUNTIF(F6:F45,">="&(0.7*F4)) -> 0 | G48: =COUNTIF(G6:G45,">="&(0.7*G4)) -> 0 | H48: =COUNTIF(H6:H45,">="&(0.7*H4)) -> 0 | I48: =COUNTIF(I6:I45,">="&(0.7*I4)) -> 0 | J48: =COUNTIF(J6:J45,">="&(0.7*J4)) -> 0 | ... L48: =COUNTIF(L6:L45,">="&(0.7*L4)) -> 0 | M48: =COUNTIF(M6:M45,">="&(0.75*M4)) -> 0 | N48: =COUNTIF(N6:N45,">="&(0.75*N4)) -> 0 | O48: =COUNTIF(O6:O45,">="&(0.75*O4)) -> 0 | P48: =COUNTIF(P6:P45,">="&(0.75*P4)) -> 0 | Q48: =COUNTIF(Q6:Q45,">="&(0.75*Q4)) -> 0 | R48: =COUNTIF(R6:R45,">="&(0.75*R4)) -> 0 | S48: =COUNTIF(S6:S45,">="&(0.75*S4)) -> 0 | T48: =COUNTIF(T6:T45,">="&(0.75*T4)) -> 0 | ... AF48: =COUNTIF(AF6:AF45,">="&(0.75*AF4)) -> 0
B51: Program PIs | C51: Fill in the colored columns with an 'x' to use the corresponding assessment against the PI | AG51: Sum | AH51: # of Assesments Included
B52: PI 1.a | AG52: =IF(AH52=0,"",SUM(C53:L53)) | AH52: =COUNT(C53:L53) -> 0
C53: =IF(C52="x",C48,"") | D53: =IF(D52="x",D48,"") | E53: =IF(E52="x",E48,"") | F53: =IF(F52="x",F48,"") | G53: =IF(G52="x",G48,"") | H53: =IF(H52="x",H48,"") | I53: =IF(I52="x",I48,"") | J53: =IF(J52="x",J48,"") | ... L53: =IF(L52="x",L48,"")
B54: PI 1.b | AG54: =IF(AH54=0,"",SUM(C55:L55)) | AH54: =COUNT(C55:L55) -> 0
C55: =IF(C54="x",C48,"") | D55: =IF(D54="x",D48,"") | E55: =IF(E54="x",E48,"") | F55: =IF(F54="x",F48,"") | G55: =IF(G54="x",G48,"") | H55: =IF(H54="x",H48,"") | I55: =IF(I54="x",I48,"") | J55: =IF(J54="x",J48,"") | ... L55: =IF(L54="x",L48,"")
B56: PI 1.c | AG56: =IF(AH56=0,"",SUM(C57:L57)) | AH56: =COUNT(C57:L57) -> 0
C57: =IF(C56="x",C48,"") | D57: =IF(D56="x",D48,"") | E57: =IF(E56="x",E48,"") | F57: =IF(F56="x",F48,"") | G57: =IF(G56="x",G48,"") | H57: =IF(H56="x",H48,"") | I57: =IF(I56="x",I48,"") | J57: =IF(J56="x",J48,"") | ... L57: =IF(L56="x",L48,"")
B58: PI 1.d | AG58: =IF(AH58=0,"",SUM(C59:L59)) | AH58: =COUNT(C59:L59) -> 0
C59: =IF(C58="x",C48,"") | D59: =IF(D58="x",D48,"") | E59: =IF(E58="x",E48,"") | F59: =IF(F58="x",F48,"") | G59: =IF(G58="x",G48,"") | H59: =IF(H58="x",H48,"") | I59: =IF(I58="x",I48,"") | J59: =IF(J58="x",J48,"") | ... L59: =IF(L58="x",L48,"")
B60: PI 2.a | AG60: =IF(AH60=0,"",SUM(C61:L61)) | AH60: =COUNT(C61:L61) -> 0
C61: =IF(C60="x",C48,"") | D61: =IF(D60="x",D48,"") | E61: =IF(E60="x",E48,"") | F61: =IF(F60="x",F48,"") | G61: =IF(G60="x",G48,"") | H61: =IF(H60="x",H48,"") | I61: =IF(I60="x",I48,"") | J61: =IF(J60="x",J48,"") | ... L61: =IF(L60="x",L48,"")
B62: PI 2.b | AG62: =IF(AH62=0,"",SUM(C63:L63)) | AH62: =COUNT(C63:L63) -> 0
C63: =IF(C62="x",C48,"") | D63: =IF(D62="x",D48,"") | E63: =IF(E62="x",E48,"") | F63: =IF(F62="x",F48,"") | G63: =IF(G62="x",G48,"") | H63: =IF(H62="x",H48,"") | I63: =IF(I62="x",I48,"") | J63: =IF(J62="x",J48,"") | ... L63: =IF(L62="x",L48,"")
B64: PI 3.a | AG64: =IF(AH64=0,"",SUM(C65:L65)) | AH64: =COUNT(C65:L65) -> 0
C65: =IF(C64="x",C48,"") | D65: =IF(D64="x",D48,"") | E65: =IF(E64="x",E48,"") | F65: =IF(F64="x",F48,"") | G65: =IF(G64="x",G48,"") | H65: =IF(H64="x",H48,"") | I65: =IF(I64="x",I48,"") | J65: =IF(J64="x",J48,"") | ... L65: =IF(L64="x",L48,"")
B66: PI 3.b | AG66: =IF(AH66=0,"",SUM(C67:L67)) | AH66: =COUNT(C67:L67) -> 0
C67: =IF(C66="x",C48,"") | D67: =IF(D66="x",D48,"") | E67: =IF(E66="x",E48,"") | F67: =IF(F66="x",F48,"") | G67: =IF(G66="x",G48,"") | H67: =IF(H66="x",H48,"") | I67: =IF(I66="x",I48,"") | J67: =IF(J66="x",J48,"") | ... L67: =IF(L66="x",L48,"")
B68: PI 3.c | AG68: =IF(AH68=0,"",SUM(C69:L69)) | AH68: =COUNT(C69:L69) -> 0
C69: =IF(C68="x",C48,"") | D69: =IF(D68="x",D48,"") | E69: =IF(E68="x",E48,"") | F69: =IF(F68="x",F48,"") | G69: =IF(G68="x",G48,"") | H69: =IF(H68="x",H48,"") | I69: =IF(I68="x",I48,"") | J69: =IF(J68="x",J48,"") | ... L69: =IF(L68="x",L48,"")
B70: PI 4.a | AG70: =IF(AH70=0,"",SUM(C71:L71)) | AH70: =COUNT(C71:L71) -> 0
...

Sheet Midterm 2
A1: Midterm Makeup - Sheet | B1: CLO # 1
B2: CLO # 2
B3: GPC Objectives
B4: Grade | C4: 1 | AI4: Total | AJ4: Course Weight
A5: Student Name | B5: ID | C5: Q 1 | D5: Q 2 | E5: Q 3 | F5: Q 4 | G5: Q 5 | H5: Q 6 | I5: Q 7 | J5: Q 8 | K5: Q 9 | L5: Q 10 | M5: Q 11 | N5: Q 12 | O5: Q13 | P5: Q 14 | Q5: Q15 | R5: Q16 | S5: Q 17 | T5: Q 18 | U5: Q19 | V5: Q 20 | W5: Q 21 | X5: Q 22 | Y5: Q 23 | Z5: Q 24 | AA5: Q 25 | AB5: Q 26 | AC5: Q 27 | AD5: Q 28 | AE5: Q 29 | AF5: Q 30 | AG5: Q 31 | AH5: Q 32 | AI5: =SUM(C4:AH4) -> 1 | AJ5: 0
A6: ='Students Names and ID'!B2 -> 0 | B6: ='Students Names and ID'!C2 -> 0 | AI6: =SUM(C6:AH6) -> 0 | AJ6: =AI6*AJ$5/(AI$5) -> 0
A7: ='Students Names and ID'!B3 -> 0 | B7: ='Students Names and ID'!C3 -> 0 | AI7: =SUM(C7:AH7) -> 0 | AJ7: =AI7*AJ$5/(AI$5) -> 0
A8: ='Students Names and ID'!B4 -> 0 | B8: ='Students Names and ID'!C4 -> 0 | AI8: =SUM(C8:AH8) -> 0 | AJ8: =AI8*AJ$5/(AI$5) -> 0
A9: ='Students Names and ID'!B5 -> 0 | B9: ='Students Names and ID'!C5 -> 0 | AI9: =SUM(C9:AH9) -> 0 | AJ9: =AI9*AJ$5/(AI$5) -> 0
A10: ='Students Names and ID'!B6 -> 0 | B10: ='Students Names and ID'!C6 -> 0 | AI10: =SUM(C10:AH10) -> 0 | AJ10: =AI10*AJ$5/(AI$5) -> 0
A11: ='Students Names and ID'!B7 -> 0 | B11: ='Students Names and ID'!C7 -> 0 | AI11: =SUM(C11:AH11) -> 0 | AJ11: =AI11*AJ$5/(AI$5) -> 0
A12: ='Students Names and ID'!B8 -> 0 | B12: ='Students Names and ID'!C8 -> 0 | AI12: =SUM(C12:AH12) -> 0 | AJ12: =AI12*AJ$5/(AI$5) -> 0
A13: ='Students Names and ID'!B9 -> 0 | B13: ='Students Names and ID'!C9 -> 0 | AI13: =SUM(C13:AH13) -> 0 | AJ13: =AI13*AJ$5/(AI$5) -> 0
A14: ='Students Names and ID'!B10 -> 0 | B14: ='Students Names and ID'!C10 -> 0 | AI14: =SUM(C14:AH14) -> 0 | AJ14: =AI14*AJ$5/(AI$5) -> 0
A15: ='Students Names and ID'!B11 -> 0 | B15: ='Students Names and ID'!C11 -> 0 | AI15: =SUM(C15:AH15) -> 0 | AJ15: =AI15*AJ$5/(AI$5) -> 0
A16: ='Students Names and ID'!B12 -> 0 | B16: ='Students Names and ID'!C12 -> 0 | AI16: =SUM(C16:AH16) -> 0 | AJ16: =AI16*AJ$5/(AI$5) -> 0
A17: ='Students Names and ID'!B13 -> 0 | B17: ='Students Names and ID'!C13 -> 0 | AI17: =SUM(C17:AH17) -> 0 | AJ17: =AI17*AJ$5/(AI$5) -> 0
... A45: ='Students Names and ID'!B41 -> 0 | B45: ='Students Names and ID'!C41 -> 0 | AI45: =SUM(C45:AH45) -> 0 | AJ45: =AI45*AJ$5/(AI$5) -> 0
B46: Average | C46: =IF(COUNTBLANK(C6:C45)=40," ",AVERAGE(C6:C45)) | D46: =IF(COUNTBLANK(D6:D45)=40," ",AVERAGE(D6:D45)) | E46: =IF(COUNTBLANK(E6:E45)=40," ",AVERAGE(E6:E45)) | F46: =IF(COUNTBLANK(F6:F45)=40," ",AVERAGE(F6:F45)) | G46: =IF(COUNTBLANK(G6:G45)=40," ",AVERAGE(G6:G45)) | H46: =IF(COUNTBLANK(H6:H45)=40," ",AVERAGE(H6:H45)) | I46: =IF(COUNTBLANK(I6:I45)=40," ",AVERAGE(I6:I45)) | J46: =IF(COUNTBLANK(J6:J45)=40," ",AVERAGE(J6:J45)) | ... AJ46: =IF(COUNTBLANK(AJ6:AJ45)=40," ",AVERAGE(AJ6:AJ45)) -> 0
B47: Average of 10 | C47: =IF(C46="","",IF(ISERROR(ROUND(C46*10/C4,1))," ",(ROUND(C46*10/C4,1)))) | D47: =IF(D46="","",IF(ISERROR(ROUND(D46*10/D4,1))," ",(ROUND(D46*10/D4,1)))) | E47: =IF(E46="","",IF(ISERROR(ROUND(E46*10/E4,1))," ",(ROUND(E46*10/E4,1)))) | F47: =IF(F46="","",IF(ISERROR(ROUND(F46*10/F4,1))," ",(ROUND(F46*10/F4,1)))) | G47: =IF(G46="","",IF(ISERROR(ROUND(G46*10/G4,1))," ",(ROUND(G46*10/G4,1)))) | H47: =IF(H46="","",IF(ISERROR(ROUND(H46*10/H4,1))," ",(ROUND(H46*10/H4,1)))) | I47: =IF(I46="","",IF(ISERROR(ROUND(I46*10/I4,1))," ",(ROUND(I46*10/I4,1)))) | J47: =IF(J46="","",IF(ISERROR(ROUND(J46*10/J4,1))," ",(ROUND(J46*10/J4,1)))) | ... AH47: =IF(AH46="","",IF(ISERROR(ROUND(AH46*10/AH4,1))," ",(ROUND(AH46*10/AH4,1)))) | AI47: =IF(AI46="","",IF(ISERROR(ROUND(AI46*10/AI5,1))," ",(ROUND(AI46*10/AI5,1)))) -> 0 | AJ47: =IF(AJ46="","",IF(ISERROR(ROUND(AJ46*10/AJ5,1))," ",(ROUND(AJ46*10/AJ5,1))))

Sheet Project
A1: Project Sheet | B1: CLO # 1
B2: CLO # 2
B3: Grade | C3: 1 | M3: Total | N3: Course Weight
A4: Student Name | B4: ID | C4: R1 | D4: R2 | E4: R3 | F4: R4 | G4: R5 | H4: R6 | I4: R7 | J4: R8 | K4: R9 | L4: R10 | M4: =SUM(C3:L3) -> 1 | N4: 0
A5: ='Students Names and ID'!B2 -> 0 | B5: ='Students Names and ID'!C2 -> 0 | M5: =SUM(C5:L5) -> 0 | N5: =M5*N4/M4 -> 0
A6: ='Students Names and ID'!B3 -> 0 | B6: ='Students Names and ID'!C3 -> 0 | M6: =SUM(C6:L6) -> 0 | N6: =M6*N4/M4 -> 0
A7: ='Students Names and ID'!B4 -> 0 | B7: ='Students Names and ID'!C4 -> 0 | M7: =SUM(C7:L7) -> 0 | N7: =M7*N4/M4 -> 0
A8: ='Students Names and ID'!B5 -> 0 | B8: ='Students Names and ID'!C5 -> 0 | M8: =SUM(C8:L8) -> 0 | N8: =M8*N4/M4 -> 0
A9: ='Students Names and ID'!B6 -> 0 | B9: ='Students Names and ID'!C6 -> 0 | M9: =SUM(C9:L9) -> 0 | N9: =M9*N4/M4 -> 0
A10: ='Students Names and ID'!B7 -> 0 | B10: ='Students Names and ID'!C7 -> 0 | M10: =SUM(C10:L10) -> 0 | N10: =M10*N4/M4 -> 0
A11: ='Students Names and ID'!B8 -> 0 | B11: ='Students Names and ID'!C8 -> 0 | M11: =SUM(C11:L11) -> 0 | N11: =M11*N4/M4 -> 0
A12: ='Students Names and ID'!B9 -> 0 | B12: ='Students Names and ID'!C9 -> 0 | M12: =SUM(C12:L12) -> 0 | N12: =M12*N4/M4 -> 0
A13: ='Students Names and ID'!B10 -> 0 | B13: ='Students Names and ID'!C10 -> 0 | M13: =SUM(C13:L13) -> 0 | N13: =M13*N4/M4 -> 0
A14: ='Students Names and ID'!B11 -> 0 | B14: ='Students Names and ID'!C11 -> 0 | M14: =SUM(C14:L14) -> 0 | N14: =M14*N4/M4 -> 0
A15: ='Students Names and ID'!B12 -> 0 | B15: ='Students Names and ID'!C12 -> 0 | M15: =SUM(C15:L15) -> 0 | N15: =M15*N4/M4 -> 0
A16: ='Students Names and ID'!B13 -> 0 | B16: ='Students Names and ID'!C13 -> 0 | M16: =SUM(C16:L16) -> 0 | N16: =M16*N4/M4 -> 0
A17: ='Students Names and ID'!B14 -> 0 | B17: ='Students Names and ID'!C14 -> 0 | M17: =SUM(C17:L17) -> 0 | N17: =M17*N4/M4 -> 0
A18: ='Students Names and ID'!B15 -> 0 | B18: ='Students Names and ID'!C15 -> 0 | M18: =SUM(C18:L18) -> 0 | N18: =M18*N4/M4 -> 0
A19: ='Students Names and ID'!B16 -> 0 | B19: ='Students Names and ID'!C16 -> 0 | M19: =SUM(C19:L19) -> 0 | N19: =M19*N4/M4 -> 0
A20: ='Students Names and ID'!B17 -> 0 | B20: ='Students Names and ID'!C17 -> 0 | M20: =SUM(C20:L20) -> 0 | N20: =M20*N4/M4 -> 0
A21: ='Students Names and ID'!B18 -> 0 | B21: ='Students Names and ID'!C18 -> 0 | M21: =SUM(C21:L21) -> 0 | N21: =M21*N4/M4 -> 0
A22: ='Students Names and ID'!B19 -> 0 | B22: ='Students Names and ID'!C19 -> 0 | M22: =SUM(C22:L22) -> 0 | N22: =M22*N4/M4 -> 0
A23: ='Students Names and ID'!B20 -> 0 | B23: ='Students Names and ID'!C20 -> 0 | M23: =SUM(C23:L23) -> 0 | N23: =M23*N4/M4 -> 0
A24: ='Students Names and ID'!B21 -> 0 | B24: ='Students Names and ID'!C21 -> 0 | M24: =SUM(C24:L24) -> 0 | N24: =M24*N4/M4 -> 0
A25: ='Students Names and ID'!B22 -> 0 | B25: ='Students Names and ID'!C22 -> 0 | M25: =SUM(C25:L25) -> 0 | N25: =M25*N4/M4 -> 0
A26: ='Students Names and ID'!B23 -> 0 | B26: ='Students Names and ID'!C23 -> 0 | M26: =SUM(C26:L26) -> 0 | N26: =M26*N4/M4 -> 0
A27: ='Students Names and ID'!B24 -> 0 | B27: ='Students Names and ID'!C24 -> 0 | M27: =SUM(C27:L27) -> 0 | N27: =M27*N4/M4 -> 0
A28: ='Students Names and ID'!B25 -> 0 | B28: ='Students Names and ID'!C25 -> 0 | M28: =SUM(C28:L28) -> 0 | N28: =M28*N4/M4 -> 0
A29: ='Students Names and ID'!B26 -> 0 | B29: ='Students Names and ID'!C26 -> 0 | M29: =SUM(C29:L29) -> 0 | N29: =M29*N4/M4 -> 0
A30: ='Students Names and ID'!B27 -> 0 | B30: ='Students Names and ID'!C27 -> 0 | M30: =SUM(C30:L30) -> 0 | N30: =M30*N4/M4 -> 0
A31: ='Students Names and ID'!B28 -> 0 | B31: ='Students Names and ID'!C28 -> 0 | M31: =SUM(C31:L31) -> 0 | N31: =M31*N4/M4 -> 0
A32: ='Students Names and ID'!B29 -> 0 | B32: ='Students Names and ID'!C29 -> 0 | M32: =SUM(C32:L32) -> 0 | N32: =M32*N4/M4 -> 0
A33: ='Students Names and ID'!B30 -> 0 | B33: ='Students Names and ID'!C30 -> 0 | M33: =SUM(C33:L33) -> 0 | N33: =M33*N4/M4 -> 0
A34: ='Students Names and ID'!B31 -> 0 | B34: ='Students Names and ID'!C31 -> 0 | M34: =SUM(C34:L34) -> 0 | N34: =M34*N4/M4 -> 0
A35: ='Students Names and ID'!B32 -> 0 | B35: ='Students Names and ID'!C32 -> 0 | M35: =SUM(C35:L35) -> 0 | N35: =M35*N4/M4 -> 0
A36: ='Students Names and ID'!B33 -> 0 | B36: ='Students Names and ID'!C33 -> 0 | M36: =SUM(C36:L36) -> 0 | N36: =M36*N4/M4 -> 0
A37: ='Students Names and ID'!B34 -> 0 | B37: ='Students Names and ID'!C34 -> 0 | M37: =SUM(C37:L37) -> 0 | N37: =M37*N4/M4 -> 0
A38: ='Students Names and ID'!B35 -> 0 | B38: ='Students Names and ID'!C35 -> 0 | M38: =SUM(C38:L38) -> 0 | N38: =M38*N4/M4 -> 0
A39: ='Students Names and ID'!B36 -> 0 | B39: ='Students Names and ID'!C36 -> 0 | M39: =SUM(C39:L39) -> 0 | N39: =M39*N4/M4 -> 0
A40: ='Students Names and ID'!B37 -> 0 | B40: ='Students Names and ID'!C37 -> 0 | M40: =SUM(C40:L40) -> 0 | N40: =M40*N4/M4 -> 0
...

Sheet Final Exam
A1: Final Exam Sheet | B1: CLO # 1
B2: CLO # 2
B3: Grade | C3: 1 | AH3: Total | AI3: Course Weight
A4: Student Name | B4: ID | C4: Q1 | D4: Q2 | E4: Q3 | F4: Q4 | G4: Q5 | H4: Q6 | I4: Q7 | J4: Q8 | K4: Q9 | L4: Q10 | M4: Q11 | N4: Q12 | O4: Q13 | P4: Q 14 | Q4: Q 15 | R4: Q 15 | S4: Q 16 | T4: Q 17 | U4: Q 18 | V4: Q 19 | W4: Q 20 | X4: Q 21 | Y4: Q 22 | Z4: Q 23 | AA4: Q 24 | AB4: Q 25 | AC4: Q 26 | AD4: Q 27 | AE4: Q 28 | AF4: Q 29 | AG4: Q 30 | AH4: =SUM(C3:AG3) -> 1 | AI4: 0
A5: ='Students Names and ID'!B2 -> 0 | B5: ='Students Names and ID'!C2 -> 0 | AH5: =SUM(C5:AG5) -> 0 | AI5: =AH5*AI$4/AH$4 -> 0
A6: ='Students Names and ID'!B3 -> 0 | B6: ='Students Names and ID'!C3 -> 0 | AH6: =SUM(C6:AG6) -> 0 | AI6: =AH6*AI$4/AH$4 -> 0
A7: ='Students Names and ID'!B4 -> 0 | B7: ='Students Names and ID'!C4 -> 0 | AH7: =SUM(C7:AG7) -> 0 | AI7: =AH7*AI$4/AH$4 -> 0
A8: ='Students Names and ID'!B5 -> 0 | B8: ='Students Names and ID'!C5 -> 0 | AH8: =SUM(C8:AG8) -> 0 | AI8: =AH8*AI$4/AH$4 -> 0
A9: ='Students Names and ID'!B6 -> 0 | B9: ='Students Names and ID'!C6 -> 0 | AH9: =SUM(C9:AG9) -> 0 | AI9: =AH9*AI$4/AH$4 -> 0
A10: ='Students Names and ID'!B7 -> 0 | B10: ='Students Names and ID'!C7 -> 0 | AH10: =SUM(C10:AG10) -> 0 | AI10: =AH10*AI$4/AH$4 -> 0
A11: ='Students Names and ID'!B8 -> 0 | B11: ='Students Names and ID'!C8 -> 0 | AH11: =SUM(C11:AG11) -> 0 | AI11: =AH11*AI$4/AH$4 -> 0
A12: ='Students Names and ID'!B9 -> 0 | B12: ='Students Names and ID'!C9 -> 0 | AH12: =SUM(C12:AG12) -> 0 | AI12: =AH12*AI$4/AH$4 -> 0
A13: ='Students Names and ID'!B10 -> 0 | B13: ='Students Names and ID'!C10 -> 0 | AH13: =SUM(C13:AG13) -> 0 | AI13: =AH13*AI$4/AH$4 -> 0
A14: ='Students Names and ID'!B11 -> 0 | B14: ='Students Names and ID'!C11 -> 0 | AH14: =SUM(C14:AG14) -> 0 | AI14: =AH14*AI$4/AH$4 -> 0
A15: ='Students Names and ID'!B12 -> 0 | B15: ='Students Names and ID'!C12 -> 0 | AH15: =SUM(C15:AG15) -> 0 | AI15: =AH15*AI$4/AH$4 -> 0
A16: ='Students Names and ID'!B13 -> 0 | B16: ='Students Names and ID'!C13 -> 0 | AH16: =SUM(C16:AG16) -> 0 | AI16: =AH16*AI$4/AH$4 -> 0
... A44: ='Students Names and ID'!B41 -> 0 | B44: ='Students Names and ID'!C41 -> 0 | AH44: =SUM(C44:AG44) -> 0 | AI44: =AH44*AI$4/AH$4 -> 0
B45: Average | C45: =IF(COUNTBLANK(C5:C44)=40," ",AVERAGE(C5:C44)) | D45: =IF(COUNTBLANK(D5:D44)=40," ",AVERAGE(D5:D44)) | E45: =IF(COUNTBLANK(E5:E44)=40," ",AVERAGE(E5:E44)) | F45: =IF(COUNTBLANK(F5:F44)=40," ",AVERAGE(F5:F44)) | G45: =IF(COUNTBLANK(G5:G44)=40," ",AVERAGE(G5:G44)) | H45: =IF(COUNTBLANK(H5:H44)=40," ",AVERAGE(H5:H44)) | N45: =IF(COUNTBLANK(N5:N44)=40," ",AVERAGE(N5:N44)) | O45: =IF(COUNTBLANK(O5:O44)=40," ",AVERAGE(O5:O44)) | W45: =IF(COUNTBLANK(W5:W44)=40," ",AVERAGE(W5:W44)) | X45: =IF(COUNTBLANK(X5:X44)=40," ",AVERAGE(X5:X44)) | Y45: =IF(COUNTBLANK(Y5:Y44)=40," ",AVERAGE(Y5:Y44)) | Z45: =IF(COUNTBLANK(Z5:Z44)=40," ",AVERAGE(Z5:Z44)) | AA45: =IF(COUNTBLANK(AA5:AA44)=40," ",AVERAGE(AA5:AA44)) | AB45: =IF(COUNTBLANK(AB5:AB44)=40," ",AVERAGE(AB5:AB44)) | AC45: =IF(COUNTBLANK(AC5:AC44)=40," ",AVERAGE(AC5:AC44)) | AD45: =IF(COUNTBLANK(AD5:AD44)=40," ",AVERAGE(AD5:AD44)) | ... AI45: =IF(COUNTBLANK(AI5:AI44)=40," ",AVERAGE(AI5:AI44)) -> 0
B46: Average of 10 | C46: =IF(C45="","",IF(ISERROR(ROUND(C45*10/C3,1))," ",(ROUND(C45*10/C3,1)))) | D46: =IF(D45="","",IF(ISERROR(ROUND(D45*10/D3,1))," ",(ROUND(D45*10/D3,1)))) | E46: =IF(E45="","",IF(ISERROR(ROUND(E45*10/E3,1))," ",(ROUND(E45*10/E3,1)))) | F46: =IF(F45="","",IF(ISERROR(ROUND(F45*10/F3,1))," ",(ROUND(F45*10/F3,1)))) | G46: =IF(G45="","",IF(ISERROR(ROUND(G45*10/G3,1))," ",(ROUND(G45*10/G3,1)))) | H46: =IF(H45="","",IF(ISERROR(ROUND(H45*10/H3,1))," ",(ROUND(H45*10/H3,1)))) | N46: =IF(N45="","",IF(ISERROR(ROUND(N45*10/N3,1))," ",(ROUND(N45*10/N3,1)))) | O46: =IF(O45="","",IF(ISERROR(ROUND(O45*10/O3,1))," ",(ROUND(O45*10/O3,1)))) | W46: =IF(W45="","",IF(ISERROR(ROUND(W45*10/W3,1))," ",(ROUND(W45*10/W3,1)))) | X46: =IF(X45="","",IF(ISERROR(ROUND(X45*10/X3,1))," ",(ROUND(X45*10/X3,1)))) | Y46: =IF(Y45="","",IF(ISERROR(ROUND(Y45*10/Y3,1))," ",(ROUND(Y45*10/Y3,1)))) | Z46: =IF(Z45="","",IF(ISERROR(ROUND(Z45*10/Z3,1))," ",(ROUND(Z45*10/Z3,1)))) | AA46: =IF(AA45="","",IF(ISERROR(ROUND(AA45*10/AA3,1))," ",(ROUND(AA45*10/AA3,1)))) | AB46: =IF(AB45="","",IF(ISERROR(ROUND(AB45*10/AB3,1))," ",(ROUND(AB45*10/AB3,1)))) | AC46: =IF(AC45="","",IF(ISERROR(ROUND(AC45*10/AC3,1))," ",(ROUND(AC45*10/AC3,1)))) | AD46: =IF(AD45="","",IF(ISERROR(ROUND(AD45*10/AD3,1))," ",(ROUND(AD45*10/AD3,1)))) | ... AG46: =IF(AG45="","",IF(ISERROR(ROUND(AG45*10/AG3,1))," ",(ROUND(AG45*10/AG3,1)))) | AH46: =IF(AH45="","",IF(ISERROR(ROUND(AH45*10/AH4,1))," ",(ROUND(AH45*10/AH4,1)))) -> 0 | AI46: =IF(AI45="","",IF(ISERROR(ROUND(AI45*10/AI4,1))," ",(ROUND(AI45*10/AI4,1))))
B48: ABET Pass Criteria | C48: =COUNTIF(C5:C44,">="&(0.7*C3)) -> 0 | D48: =COUNTIF(D5:D44,">="&(0.7*D3)) -> 0 | E48: =COUNTIF(E5:E44,">="&(0.7*E3)) -> 0 | F48: =COUNTIF(F5:F44,">="&(0.7*F3)) -> 0 | G48: =COUNTIF(G5:G44,">="&(0.7*G3)) -> 0 | H48: =COUNTIF(H5:H44,">="&(0.7*H3)) -> 0 | I48: =COUNTIF(I5:I44,">="&(0.7*I3)) -> 0 | J48: =COUNTIF(J5:J44,">="&(0.7*J3)) -> 0 | ... AG48: =COUNTIF(AG5:AG44,">="&(0.7*AG3)) -> 0
C50: =C4 -> Q1 | D50: =D4 -> Q2 | E50: =E4 -> Q3 | F50: =F4 -> Q4 | G50: =G4 -> Q5 | H50: =H4 -> Q6 | I50: =I4 -> Q7 | J50: =J4 -> Q8 | ... L50: =L4 -> Q10
B51: Program PIs | C51: Fill in the colored columns with an 'x' to use the corresponding assessment against the PI | AH51: Sum | AI51: # of Asses. Included
C52: Do not write in the white columns
B53: PI 1.a | AH53: =IF(AI53=0,"",SUM(C54:L54)) | AI53: =COUNT(C54:L54) -> 0
C54: =IF(C53="x",C48,"") | D54: =IF(D53="x",D48,"") | E54: =IF(E53="x",E48,"") | F54: =IF(F53="x",F48,"") | G54: =IF(G53="x",G48,"") | H54: =IF(H53="x",H48,"") | I54: =IF(I53="x",I48,"") | J54: =IF(J53="x",J48,"") | ... L54: =IF(L53="x",L48,"")
B55: PI 1.b | AH55: =IF(AI55=0,"",SUM(C56:L56)) | AI55: =COUNT(C56:L56) -> 0
C56: =IF(C55="x",C48,"") | D56: =IF(D55="x",D48,"") | E56: =IF(E55="x",E48,"") | F56: =IF(F55="x",F48,"") | G56: =IF(G55="x",G48,"") | H56: =IF(H55="x",H48,"") | I56: =IF(I55="x",I48,"") | J56: =IF(J55="x",J48,"") | ... L56: =IF(L55="x",L48,"")
B57: PI 1.c | AH57: =IF(AI57=0,"",SUM(C58:L58)) | AI57: =COUNT(C58:L58) -> 0
C58: =IF(C57="x",C48,"") | D58: =IF(D57="x",D48,"") | E58: =IF(E57="x",E48,"") | F58: =IF(F57="x",F48,"") | G58: =IF(G57="x",G48,"") | H58: =IF(H57="x",H48,"") | I58: =IF(I57="x",I48,"") | J58: =IF(J57="x",J48,"") | ... L58: =IF(L57="x",L48,"")
B59: PI 1.d | AH59: =IF(AI59=0,"",SUM(C60:L60)) | AI59: =COUNT(C60:L60) -> 0
C60: =IF(C59="x",C48,"") | D60: =IF(D59="x",D48,"") | E60: =IF(E59="x",E48,"") | F60: =IF(F59="x",F48,"") | G60: =IF(G59="x",G48,"") | H60: =IF(H59="x",H48,"") | I60: =IF(I59="x",I48,"") | J60: =IF(J59="x",J48,"") | ... L60: =IF(L59="x",L48,"")
B61: PI 2.a | AH61: =IF(AI61=0,"",SUM(C62:L62)) | AI61: =COUNT(C62:L62) -> 0
C62: =IF(C61="x",C48,"") | D62: =IF(D61="x",D48,"") | E62: =IF(E61="x",E48,"") | F62: =IF(F61="x",F48,"") | G62: =IF(G61="x",G48,"") | H62: =IF(H61="x",H48,"") | I62: =IF(I61="x",I48,"") | J62: =IF(J61="x",J48,"") | ... L62: =IF(L61="x",L48,"")
B63: PI 2.b | AH63: =IF(AI63=0,"",SUM(C64:L64)) | AI63: =COUNT(C64:L64) -> 0
C64: =IF(C63="x",C48,"") | D64: =IF(D63="x",D48,"") | E64: =IF(E63="x",E48,"") | F64: =IF(F63="x",F48,"") | G64: =IF(G63="x",G48,"") | H64: =IF(H63="x",H48,"") | I64: =IF(I63="x",I48,"") | J64: =IF(J63="x",J48,"") | ... L64: =IF(L63="x",L48,"")
B65: PI 3.a | AH65: =IF(AI65=0,"",SUM(C66:L66)) | AI65: =COUNT(C66:L66) -> 0
C66: =IF(C65="x",C48,"") | D66: =IF(D65="x",D48,"") | E66: =IF(E65="x",E48,"") | F66: =IF(F65="x",F48,"") | G66: =IF(G65="x",G48,"") | H66: =IF(H65="x",H48,"") | I66: =IF(I65="x",I48,"") | J66: =IF(J65="x",J48,"") | ... L66: =IF(L65="x",L48,"")
B67: PI 3.b | AH67: =IF(AI67=0,"",SUM(C68:L68)) | AI67: =COUNT(C68:L68) -> 0
C68: =IF(C67="x",C48,"") | D68: =IF(D67="x",D48,"") | E68: =IF(E67="x",E48,"") | F68: =IF(F67="x",F48,"") | G68: =IF(G67="x",G48,"") | H68: =IF(H67="x",H48,"") | I68: =IF(I67="x",I48,"") | J68: =IF(J67="x",J48,"") | ... L68: =IF(L67="x",L48,"")
B69: PI 3.c | AH69: =IF(AI69=0,"",SUM(C70:L70)) | AI69: =COUNT(C70:L70) -> 0
...

Sheet Incomplete Final
A1: Incomplete Final Exam - Sheet | B1: CLO # 1
B2: CLO # 2
B3: Grade | C3: 1 | AH3: Total | AI3: Course Weight
A4: Student Name | B4: ID | C4: Q1 | D4: Q2 | E4: Q3 | F4: Q4 | G4: Q5 | H4: Q6 | I4: Q7 | J4: Q8 | K4: Q9 | L4: Q10 | M4: Q11 | N4: Q12 | O4: Q13 | P4: Q 14 | Q4: Q 15 | R4: Q 15 | S4: Q 16 | T4: Q 17 | U4: Q 18 | V4: Q 19 | W4: Q 20 | X4: Q 21 | Y4: Q 22 | Z4: Q 23 | AA4: Q 24 | AB4: Q 25 | AC4: Q 26 | AD4: Q 27 | AE4: Q 28 | AF4: Q 29 | AG4: Q 30 | AH4: =SUM(C3:AG3) -> 1 | AI4: 0
A5: ='Students Names and ID'!B2 -> 0 | B5: ='Students Names and ID'!C2 -> 0 | AH5: =SUM(C5:AG5) -> 0 | AI5: =AH5*AI$4/AH$4 -> 0
A6: ='Students Names and ID'!B3 -> 0 | B6: ='Students Names and ID'!C3 -> 0 | AH6: =SUM(C6:AG6) -> 0 | AI6: =AH6*AI$4/AH$4 -> 0
A7: ='Students Names and ID'!B4 -> 0 | B7: ='Students Names and ID'!C4 -> 0 | AH7: =SUM(C7:AG7) -> 0 | AI7: =AH7*AI$4/AH$4 -> 0
A8: ='Students Names and ID'!B5 -> 0 | B8: ='Students Names and ID'!C5 -> 0 | AH8: =SUM(C8:AG8) -> 0 | AI8: =AH8*AI$4/AH$4 -> 0
A9: ='Students Names and ID'!B6 -> 0 | B9: ='Students Names and ID'!C6 -> 0 | AH9: =SUM(C9:AG9) -> 0 | AI9: =AH9*AI$4/AH$4 -> 0
A10: ='Students Names and ID'!B7 -> 0 | B10: ='Students Names and ID'!C7 -> 0 | AH10: =SUM(C10:AG10) -> 0 | AI10: =AH10*AI$4/AH$4 -> 0
A11: ='Students Names and ID'!B8 -> 0 | B11: ='Students Names and ID'!C8 -> 0 | AH11: =SUM(C11:AG11) -> 0 | AI11: =AH11*AI$4/AH$4 -> 0
A12: ='Students Names and ID'!B9 -> 0 | B12: ='Students Names and ID'!C9 -> 0 | AH12: =SUM(C12:AG12) -> 0 | AI12: =AH12*AI$4/AH$4 -> 0
A13: ='Students Names and ID'!B10 -> 0 | B13: ='Students Names and ID'!C10 -> 0 | AH13: =SUM(C13:AG13) -> 0 | AI13: =AH13*AI$4/AH$4 -> 0
A14: ='Students Names and ID'!B11 -> 0 | B14: ='Students Names and ID'!C11 -> 0 | AH14: =SUM(C14:AG14) -> 0 | AI14: =AH14*AI$4/AH$4 -> 0
A15: ='Students Names and ID'!B12 -> 0 | B15: ='Students Names and ID'!C12 -> 0 | AH15: =SUM(C15:AG15) -> 0 | AI15: =AH15*AI$4/AH$4 -> 0
A16: ='Students Names and ID'!B13 -> 0 | B16: ='Students Names and ID'!C13 -> 0 | AH16: =SUM(C16:AG16) -> 0 | AI16: =AH16*AI$4/AH$4 -> 0
... A44: ='Students Names and ID'!B41 -> 0 | B44: ='Students Names and ID'!C41 -> 0 | AH44: =SUM(C44:AG44) -> 0 | AI44: =AH44*AI$4/AH$4 -> 0
B45: Average | C45: =IF(COUNTBLANK(C5:C44)=40," ",AVERAGE(C5:C44)) | D45: =IF(COUNTBLANK(D5:D44)=40," ",AVERAGE(D5:D44)) | E45: =IF(COUNTBLANK(E5:E44)=40," ",AVERAGE(E5:E44)) | F45: =IF(COUNTBLANK(F5:F44)=40," ",AVERAGE(F5:F44)) | G45: =IF(COUNTBLANK(G5:G44)=40," ",AVERAGE(G5:G44)) | H45: =IF(COUNTBLANK(H5:H44)=40," ",AVERAGE(H5:H44)) | N45: =IF(COUNTBLANK(N5:N44)=40," ",AVERAGE(N5:N44)) | O45: =IF(COUNTBLANK(O5:O44)=40," ",AVERAGE(O5:O44)) | W45: =IF(COUNTBLANK(W5:W44)=40," ",AVERAGE(W5:W44)) | X45: =IF(COUNTBLANK(X5:X44)=40," ",AVERAGE(X5:X44)) | Y45: =IF(COUNTBLANK(Y5:Y44)=40," ",AVERAGE(Y5:Y44)) | Z45: =IF(COUNTBLANK(Z5:Z44)=40," ",AVERAGE(Z5:Z44)) | AA45: =IF(COUNTBLANK(AA5:AA44)=40," ",AVERAGE(AA5:AA44)) | AB45: =IF(COUNTBLANK(AB5:AB44)=40," ",AVERAGE(AB5:AB44)) | AC45: =IF(COUNTBLANK(AC5:AC44)=40," ",AVERAGE(AC5:AC44)) | AD45: =IF(COUNTBLANK(AD5:AD44)=40," ",AVERAGE(AD5:AD44)) | ... AI45: =IF(COUNTBLANK(AI5:AI44)=40," ",AVERAGE(AI5:AI44)) -> 0
